<?xml version="1.0" encoding="utf-8"?>

<robot name="dzy_arm"  xmlns:xacro="http://www.ros.org/wiki/xacro">

<!--macro for wajueji description -->
  <xacro:macro name="arm">

  <!--  A base_footprint link and joint for KDL solver  -->
  <link name="base_footprint" />

  <joint name="base_footprint_joint" type="fixed">
     <parent link="base_footprint"/>
     <child link="base_link"/>
  </joint>

  <link
    name="base_link">
    <inertial>
      <origin
        xyz="-1.6653E-16 0 0.017899"
        rpy="0 0 0" />
      <mass
        value="200" />
      <inertia
        ixx="0.74805"
        ixy="7.5539E-17"
        ixz="2.5654E-17"
        iyy="2.899"
        iyz="6.0732E-18"
        izz="3.6414" />
    </inertial>
    <visual>
      <origin
        xyz="0 0 0"
        rpy="0 0 0" />
      <geometry>
        <mesh
          filename="package://dzy_arm/meshes/base_link.STL" />
      </geometry>
      <material
        name="">
        <color
          rgba="0.79216 0.81961 0.93333 1" />
      </material>
    </visual>
    <collision>
      <origin
        xyz="0 0 0"
        rpy="0 0 0" />
      <geometry>
        <mesh
          filename="package://dzy_arm/meshes/base_link.STL" />
      </geometry>
    </collision>
  </link>

  <link
    name="arm_base">
    <inertial>
      <origin
        xyz="0.00022082 0.0013404 0.025529"
        rpy="0 0 0" />
      <mass
        value="1" />
      <inertia
        ixx="0.0012705"
        ixy="6.1222E-06"
        ixz="1.9781E-06"
        iyy="0.0013414"
        iyz="1.2005E-05"
        izz="0.0022565" />
    </inertial>
    <visual>
      <origin
        xyz="0 0 0"
        rpy="0 0 0" />
      <geometry>
        <mesh
          filename="package://dzy_arm/meshes/arm_base.STL" />
      </geometry>
      <material
        name="">
        <color
          rgba="0.50196 0.50196 0.50196 1" />
      </material>
    </visual>
    <collision>
      <origin
        xyz="0 0 0"
        rpy="0 0 0" />
      <geometry>
        <mesh
          filename="package://dzy_arm/meshes/arm_base.STL" />
      </geometry>
    </collision>
  </link>

  <joint
    name="base_arm"
    type="fixed">
    <origin
      xyz="0 -0.22 0.04"
      rpy="0 0 0" />
    <parent
      link="base_link" />
    <child
      link="arm_base" />
    <axis
      xyz="0 0 0" />
  </joint>

  <link
    name="arm_25a">
    <inertial>
      <origin
        xyz="-0.021816 -1.2947E-05 0.095392"
        rpy="0 0 0" />
      <mass
        value="2.5856" />
      <inertia
        ixx="0.012636"
        ixy="2.0018E-06"
        ixz="0.0034175"
        iyy="0.014362"
        iyz="1.787E-06"
        izz="0.0066119" />
    </inertial>
    <visual>
      <origin
        xyz="0 0 0"
        rpy="0 0 0" />
      <geometry>
        <mesh
          filename="package://dzy_arm/meshes/arm_25a.STL" />
      </geometry>
      <material
        name="">
        <color
          rgba="0.76863 0.74902 0.72941 1" />
      </material>
    </visual>
    <collision>
      <origin
        xyz="0 0 0"
        rpy="0 0 0" />
      <geometry>
        <mesh
          filename="package://dzy_arm/meshes/arm_25a.STL" />
      </geometry>
    </collision>
  </link>

  <joint
    name="base_25a"
    type="revolute">
    <origin
      xyz="0 0 0.0735"
      rpy="0 0 0" />
    <parent
      link="arm_base" />
    <child
      link="arm_25a" />
    <axis
      xyz="0 0 -1" />
    <limit
      lower="-3.14"
      upper="3.14"
      effort="100"
      velocity="1" />
  </joint>

  <link
    name="arm_arm1">
    <inertial>
      <origin
        xyz="-0.043499 8.6926E-07 0.15814"
        rpy="0 0 0" />
      <mass
        value="1.2132" />
      <inertia
        ixx="0.015967"
        ixy="1.048E-07"
        ixz="-0.00048306"
        iyy="0.015469"
        iyz="1.2117E-06"
        izz="0.0015138" />
    </inertial>
    <visual>
      <origin
        xyz="0 0 0"
        rpy="0 0 0" />
      <geometry>
        <mesh
          filename="package://dzy_arm/meshes/arm_arm1.STL" />
      </geometry>
      <material
        name="">
        <color
          rgba="1 1 1 1" />
      </material>
    </visual>
    <collision>
      <origin
        xyz="0 0 0"
        rpy="0 0 0" />
      <geometry>
        <mesh
          filename="package://dzy_arm/meshes/arm_arm1.STL" />
      </geometry>
    </collision>
  </link>

  <joint
    name="a25_arm1"
    type="revolute">
    <origin
      xyz="-0.087 0 0.1465"
      rpy="0 0 0" />
    <parent
      link="arm_25a" />
    <child
      link="arm_arm1" />
    <axis
      xyz="-1 0 0" />
    <limit
      lower="-1.57"
      upper="1.57"
      effort="100"
      velocity="1" />
  </joint>

  <link
    name="arm_20a">
    <inertial>
      <origin
        xyz="0.061087 0.04148 9.6811E-06"
        rpy="0 0 0" />
      <mass
        value="1.5325" />
      <inertia
        ixx="0.00514"
        ixy="-0.0014835"
        ixz="6.4705E-07"
        iyy="0.0028928"
        iyz="-3.2735E-07"
        izz="0.0060883" />
    </inertial>
    <visual>
      <origin
        xyz="0 0 0"
        rpy="0 0 0" />
      <geometry>
        <mesh
          filename="package://dzy_arm/meshes/arm_20a.STL" />
      </geometry>
      <material
        name="">
        <color
          rgba="0.86667 0.86667 0.8902 1" />
      </material>
    </visual>
    <collision>
      <origin
        xyz="0 0 0"
        rpy="0 0 0" />
      <geometry>
        <mesh
          filename="package://dzy_arm/meshes/arm_20a.STL" />
      </geometry>
    </collision>
  </link>

  <joint
    name="arm1_20a"
    type="revolute">
    <origin
      xyz="0.0065 0 0.38"
      rpy="0 0 0" />
    <parent
      link="arm_arm1" />
    <child
      link="arm_20a" />
    <axis
      xyz="1 0 0" />
    <limit
      lower="-1.57"
      upper="4.71"
      effort="100"
      velocity="1" />
  </joint>

  <link
    name="arm_arm2">
    <inertial>
      <origin
        xyz="0.058943 0.13208 4.682E-05"
        rpy="0 0 0" />
      <mass
        value="0.47523" />
      <inertia
        ixx="0.0048651"
        ixy="-0.0012955"
        ixz="-8.1233E-07"
        iyy="0.0011888"
        iyz="-2.5078E-06"
        izz="0.0053838" />
    </inertial>
    <visual>
      <origin
        xyz="0 0 0"
        rpy="0 0 0" />
      <geometry>
        <mesh
          filename="package://dzy_arm/meshes/arm_arm2.STL" />
      </geometry>
      <material
        name="">
        <color
          rgba="0.76863 0.74902 0.72941 1" />
      </material>
    </visual>
    <collision>
      <origin
        xyz="0 0 0"
        rpy="0 0 0" />
      <geometry>
        <mesh
          filename="package://dzy_arm/meshes/arm_arm2.STL" />
      </geometry>
    </collision>
  </link>

  <joint
    name="a20_arm2"
    type="revolute">
    <origin
      xyz="0.0805 0.125 0"
      rpy="0 0 0" />
    <parent
      link="arm_20a" />
    <child
      link="arm_arm2" />
    <axis
      xyz="0 1 0" />
    <limit
      lower="-3.14"
      upper="3.14"
      effort="100"
      velocity="1" />
  </joint>

  <link
    name="arm_14a">
    <inertial>
      <origin
        xyz="-0.054028 1.9783E-06 -0.036591"
        rpy="0 0 0" />
      <mass
        value="0.81191" />
      <inertia
        ixx="0.0018901"
        ixy="5.3746E-08"
        ixz="-0.0005673"
        iyy="0.002299"
        iyz="-1.1157E-08"
        izz="0.0010232" />
    </inertial>
    <visual>
      <origin
        xyz="0 0 0"
        rpy="0 0 0" />
      <geometry>
        <mesh
          filename="package://dzy_arm/meshes/arm_14a.STL" />
      </geometry>
      <material
        name="">
        <color
          rgba="1 1 1 1" />
      </material>
    </visual>
    <collision>
      <origin
        xyz="0 0 0"
        rpy="0 0 0" />
      <geometry>
        <mesh
          filename="package://dzy_arm/meshes/arm_14a.STL" />
      </geometry>
    </collision>
  </link>

  <joint
    name="arm2_14a"
    type="revolute">
    <origin
      xyz="0.07 0.295 0"
      rpy="0 0 0" />
    <parent
      link="arm_arm2" />
    <child
      link="arm_14a" />
    <axis
      xyz="-1 0 0" />
    <limit
      lower="-4.71"
      upper="1.57"
      effort="100"
      velocity="1" />
  </joint>

  <link
    name="arm_adapter">
    <inertial>
      <origin
        xyz="-0.0073581 3.2498E-05 0.012838"
        rpy="0 0 0" />
      <mass
        value="0.11183" />
      <inertia
        ixx="7.4896E-05"
        ixy="-1.8612E-07"
        ixz="2.3431E-06"
        iyy="7.6625E-05"
        iyz="4.6601E-08"
        izz="0.00012779" />
    </inertial>
    <visual>
      <origin
        xyz="0 0 0"
        rpy="0 0 0" />
      <geometry>
        <mesh
          filename="package://dzy_arm/meshes/arm_adapter.STL" />
      </geometry>
      <material
        name="">
        <color
          rgba="0.79216 0.81961 0.92941 1" />
      </material>
    </visual>
    <collision>
      <origin
        xyz="0 0 0"
        rpy="0 0 0" />
      <geometry>
        <mesh
          filename="package://dzy_arm/meshes/arm_adapter.STL" />
      </geometry>
    </collision>
  </link>

  <joint
    name="a14_adapter"
    type="revolute">
    <origin
      xyz="-0.07 0 -0.1465"
      rpy="0 0 0.0074728" />
    <parent
      link="arm_14a" />
    <child
      link="arm_adapter" />
    <axis
      xyz="0 0 -1" />
    <limit
      lower="-3.14"
      upper="3.14"
      effort="100"
      velocity="1" />
  </joint>

  <link
    name="pin">
    <inertial>
      <origin
        xyz="-1.9429E-16 5.5511E-17 -0.0035664"
        rpy="0 0 0" />
      <mass
        value="0.011493" />
      <inertia
        ixx="3.0087E-06"
        ixy="3.1764E-22"
        ixz="1.2884E-20"
        iyy="3.0087E-06"
        iyz="-5.3363E-21"
        izz="4.5628E-06" />
    </inertial>
    <visual>
      <origin
        xyz="0 0 0"
        rpy="0 0 0" />
      <geometry>
        <mesh
          filename="package://dzy_arm/meshes/pin.STL" />
      </geometry>
      <material
        name="">
        <color
          rgba="0.79216 0.81961 0.93333 1" />
      </material>
    </visual>
    <collision>
      <origin
        xyz="0 0 0"
        rpy="0 0 0" />
      <geometry>
        <mesh
          filename="package://dzy_arm/meshes/pin.STL" />
      </geometry>
    </collision>
  </link>

  <joint
    name="adapter_pin"
    type="fixed">
    <origin
      xyz="0 0 -0.0085"
      rpy="0 0 -0.3927" />
    <parent
      link="arm_adapter" />
    <child
      link="pin" />
    <axis
      xyz="0 0 0" />
  </joint>

  <link
    name="tou">
    <inertial>
      <origin
        xyz="0 -1.7347E-18 -0.0009375"
        rpy="0 0 0" />
      <mass
        value="0.01" />
      <inertia
        ixx="5.305E-11"
        ixy="-7.1033E-40"
        ixz="-9.2266E-26"
        iyy="5.305E-11"
        iyz="2.0039E-25"
        izz="8.1812E-11" />
    </inertial>
    <visual>
      <origin
        xyz="0 0 0"
        rpy="0 0 0" />
      <geometry>
        <mesh
          filename="package://dzy_arm/meshes/tou.STL" />
      </geometry>
      <material
        name="">
        <color
          rgba="0.79216 0.81961 0.93333 1" />
      </material>
    </visual>
    <collision>
      <origin
        xyz="0 0 0"
        rpy="0 0 0" />
      <geometry>
        <mesh
          filename="package://dzy_arm/meshes/tou.STL" />
      </geometry>
    </collision>
  </link>

  <joint
    name="pin_tou"
    type="continuous">
    <origin
      xyz="0 0 -0.058"
      rpy="0 0 -1.1856" />
    <parent
      link="pin" />
    <child
      link="tou" />
    <axis
      xyz="0 0 1" />
  </joint>

  </xacro:macro>
</robot>
